<robot name="robot_Practica2" version="1.0">
  <joint name="base_gripper_link_joint" type="fixed">
    <origin rpy="0.00000 0.00000 0.00000" xyz="-0.51563 0.00006 0.72658"/>
    <parent link="base_link"/>
    <child link="base_gripper_link"/>
  </joint>
  <joint name="arm_1_link_joint" type="revolute">
    <origin rpy="0 0 0" xyz="0 0 0.74424"/>
    <parent link="base_gripper_link"/>
    <child link="arm_1_link"/>
    <axis xyz="0 0 1"/>
    <limit lower="-3.14" upper="3.14" effort="50" velocity="2"/>
  </joint>
  <joint name="wheelA_3_link_joint" type="continuous">
    <limit effort="0.00000" velocity="0.00000"/>
    <origin rpy="1.57080 0.00000 0.00000" xyz="2.23201 1.32843 -0.83009"/>
    <parent link="base_link"/>
    <child link="wheelA_3_link"/>
    <axis xyz="0.00000 0.00000 1.00000"/>
  </joint>
  <joint name="wheelB_1_link_joint" type="continuous">
    <limit effort="0.00000" velocity="0.00000"/>
    <origin rpy="1.57080 0.00000 0.00000" xyz="-1.07987 -1.32831 -0.83009"/>
    <parent link="base_link"/>
    <child link="wheelB_1_link"/>
    <axis xyz="0.00000 0.00000 1.00000"/>
  </joint>
  <joint name="wheelB_2_link_joint" type="continuous">
    <limit effort="0.00000" velocity="0.00000"/>
    <origin rpy="1.57080 0.00000 0.00000" xyz="0.65003 -1.32832 -0.83009"/>
    <parent link="base_link"/>
    <child link="wheelB_2_link"/>
    <axis xyz="0.00000 0.00000 1.00000"/>
  </joint>
  <joint name="wheelB_3_link_joint" type="continuous">
    <limit effort="0.00000" velocity="0.00000"/>
    <origin rpy="1.57080 0.00000 0.00000" xyz="2.23201 -1.32832 -0.83009"/>
    <parent link="base_link"/>
    <child link="wheelB_3_link"/>
    <axis xyz="0.00000 0.00000 1.00000"/>
  </joint>
  <joint name="arm_2_link_joint" type="revolute">
    <origin rpy="0 0 0" xyz="-1.46 0 0.15"/>
    <parent link="arm_1_link"/>
    <child link="arm_2_link"/>
    <axis xyz="0 0 1"/>
    <limit lower="-2.356" upper="2.356" effort="50" velocity="2"/>
  </joint>
  <joint name="arm_3_link_joint" type="revolute">
    <origin rpy="0 0 0" xyz="-1.46 0 -0.11"/>
    <parent link="arm_2_link"/>
    <child link="arm_3_link"/>
    <axis xyz="0 0 1"/>
    <limit lower="-3.14" upper="3.14" effort="50" velocity="2"/>
  </joint>
  <joint name="arm_4_link_joint" type="prismatic">
    <origin rpy="0 0 0" xyz="0 0 -1.05"/>
    <parent link="arm_3_link"/>
    <child link="arm_4_link"/>
    <axis xyz="0 0 1"/>
    <limit lower="-0.38" upper="1.5" effort="50" velocity="1.0"/>
  </joint>
  <joint name="base_endEffector_link_joint" type="fixed">
    <origin rpy="0 0 0" xyz="0 0 -0.73"/>
    <parent link="arm_4_link"/>
    <child link="base_endEffector_link"/>
  </joint>
  <joint name="gripper_1_link_joint" type="prismatic">
    <origin rpy="-1.5708 0 0" xyz="0 -0.36 -0.24"/>
    <parent link="base_endEffector_link"/>
    <child link="gripper_1_link"/>
    <axis xyz="0 0 1"/>
    <limit lower="0.0" upper="0.25" effort="20" velocity="1.0"/>
  </joint>
  <joint name="gripper_2_link_joint" type="prismatic">
    <origin rpy="1.5708 0 0" xyz="0 0.36 -0.24"/>
    <parent link="base_endEffector_link"/>
    <child link="gripper_2_link"/>
    <axis xyz="0 0 1"/>
    <limit lower="0.0" upper="0.25" effort="20" velocity="1.0"/>
  </joint>
  <joint name="wheelA_1_link_joint" type="continuous">
    <limit effort="0.00000" velocity="0.00000"/>
    <origin rpy="1.57080 0.00000 0.00000" xyz="-1.07987 1.32843 -0.83009"/>
    <parent link="base_link"/>
    <child link="wheelA_1_link"/>
    <axis xyz="0.00000 0.00000 1.00000"/>
  </joint>
  <joint name="wheelA_2_link_joint" type="continuous">
    <limit effort="0.00000" velocity="0.00000"/>
    <origin rpy="1.57080 0.00000 0.00000" xyz="0.65003 1.32843 -0.83009"/>
    <parent link="base_link"/>
    <child link="wheelA_2_link"/>
    <axis xyz="0.00000 0.00000 1.00000"/>
  </joint>
  <link name="base_link">
    <!-- SUELO CAJA -->
    <collision name="floor_right">
      <origin xyz="1.35 0 -0.15" rpy="0 0 0"/>
      <geometry>
        <box size="1.9 1.9 0.05"/>
      </geometry>
    </collision>

    <!-- PARED DERECHA -->
    <collision name="wall_right">
      <origin xyz="2.30 0 0.10" rpy="0 0 0"/>
      <geometry>
        <box size="0.05 1.9 0.6"/>
      </geometry>
    </collision>

    <!-- PARED CENTRAL -->
    <collision name="wall_middle">
      <origin xyz="0.40 0 0.10" rpy="0 0 0"/>
      <geometry>
        <box size="0.05 1.9 0.6"/>
      </geometry>
    </collision>

    <!-- PARED TRASERA -->
    <collision name="wall_back">
      <origin xyz="1.35 -0.95 0.10" rpy="0 0 0"/>
      <geometry>
        <box size="1.9 0.05 0.6"/>
      </geometry>
    </collision>

    <!-- PARED FRONTAL -->
    <collision name="wall_front">
      <origin xyz="1.35 0.95 0.10" rpy="0 0 0"/>
      <geometry>
        <box size="1.9 0.05 0.6"/>
      </geometry>
    </collision>

    <!-- PLATAFORMA -->
    <collision name="platform_left">
      <origin xyz="-0.60 0 0.10" rpy="0 0 0"/>
      <geometry>
        <box size="2.4 2.2 0.05"/>
      </geometry>
    </collision>
    <inertial>
      <inertia ixx="41.28289" ixy="-0.00802" ixz="9.08471" iyy="106.15301" iyz="0.02896" izz="122.29248"/>
      <origin rpy="0.00000 0.00000 0.00000" xyz="-0.00000 -0.00000 -0.00000"/>
      <mass value="80.00000"/>
    </inertial>
    <visual name="base">
      <material name="None"/>
      <origin rpy="0.00000 0.00000 0.00000" xyz="0.00000 0.00000 -0.00000"/>
      <geometry>
        <mesh filename="../meshes/dae/Cube.005.dae" scale="2.00000 1.00000 0.05000"/>
      </geometry>
    </visual>
  </link>
  <link name="base_gripper_link">
    <collision name="base_gripper_collision">
      <origin rpy="0.00000 0.00000 0.00000" xyz="0.00000 -0.00000 0.00000"/>
      <geometry>
        <mesh filename="../meshes/dae/Cylinder.dae" scale="0.70000 0.75000 0.07647"/>
      </geometry>
    </collision>
    <inertial>
      <inertia ixx="3.73641" ixy="-0.00000" ixz="-0.00000" iyy="3.48927" iyz="0.00000" izz="3.61756"/>
      <origin rpy="0.00000 0.00000 0.00000" xyz="-0.00000 -0.00000 -0.17512"/>
      <mass value="20.00000"/>
    </inertial>
    <visual name="base_gripper">
      <material name="None"/>
      <origin rpy="0.00000 0.00000 0.00000" xyz="-0.00000 -0.00000 0.00000"/>
      <geometry>
        <mesh filename="../meshes/dae/Cylinder.dae" scale="0.70000 0.75000 0.07647"/>
      </geometry>
    </visual>
  </link>
  <link name="wheelA_2_link">
    <collision name="wheelA_2_collision">
      <origin rpy="0.00000 0.00000 0.00000" xyz="-0.00000 0.00000 -0.04000"/>
      <geometry>
        <mesh filename="../meshes/dae/Torus.004.dae" scale="0.32000 0.32000 0.80000"/>
      </geometry>
    </collision>
    <inertial>
      <inertia ixx="0.22705" ixy="0.00000" ixz="0.00000" iyy="0.37534" iyz="-0.00000" izz="0.22705"/>
      <origin rpy="0.00000 0.00000 0.00000" xyz="-0.00000 0.00000 -0.04000"/>
      <mass value="5.00000"/>
    </inertial>
    <visual name="wheelA_2">
      <material name="None"/>
      <origin rpy="0.00000 0.00000 0.00000" xyz="-0.00000 0.00000 -0.04000"/>
      <geometry>
        <mesh filename="../meshes/dae/Torus.004.dae" scale="0.32000 0.32000 0.80000"/>
      </geometry>
    </visual>
  </link>
  <link name="wheelA_3_link">
    <collision name="wheelA_3_collision">
      <origin rpy="0.00000 0.00000 0.00000" xyz="0.00000 0.00000 -0.04000"/>
      <geometry>
        <mesh filename="../meshes/dae/Torus.003.dae" scale="0.32000 0.32000 0.80000"/>
      </geometry>
    </collision>
    <inertial>
      <inertia ixx="0.22705" ixy="0.00000" ixz="0.00000" iyy="0.37534" iyz="-0.00000" izz="0.22705"/>
      <origin rpy="0.00000 0.00000 0.00000" xyz="0.00000 0.00000 -0.04000"/>
      <mass value="5.00000"/>
    </inertial>
    <visual name="wheelA_3">
      <material name="None"/>
      <origin rpy="0.00000 0.00000 0.00000" xyz="0.00000 0.00000 -0.04000"/>
      <geometry>
        <mesh filename="../meshes/dae/Torus.003.dae" scale="0.32000 0.32000 0.80000"/>
      </geometry>
    </visual>
  </link>
  <link name="wheelB_1_link">
    <collision name="wheelB_1_collision">
      <origin rpy="0.00000 0.00000 0.00000" xyz="0.00000 0.00000 0.04000"/>
      <geometry>
        <mesh filename="../meshes/dae/Torus.dae" scale="0.32000 0.32000 0.80000"/>
      </geometry>
    </collision>
    <visual name="wheelB_1">
      <material name="None"/>
      <origin rpy="0.00000 0.00000 0.00000" xyz="0.00000 -0.00000 0.04000"/>
      <geometry>
        <mesh filename="../meshes/dae/Torus.dae" scale="0.32000 0.32000 0.80000"/>
      </geometry>
    </visual>
    <inertial>
      <origin xyz="0 0 0" rpy="0 0 0"/>
      <mass value="2.0"/>
      <inertia ixx="0.05" ixy="0.0" ixz="0.0"
              iyy="0.05" iyz="0.0"
              izz="0.05"/>
    </inertial>
  </link>
  <link name="wheelB_2_link">
    <collision name="wheelB_2_collision">
      <origin rpy="0.00000 0.00000 0.00000" xyz="-0.00000 0.00000 0.04000"/>
      <geometry>
        <mesh filename="../meshes/dae/Torus.001.dae" scale="0.32000 0.32000 0.80000"/>
      </geometry>
    </collision>
    <inertial>
      <inertia ixx="0.22705" ixy="0.00000" ixz="0.00000" iyy="0.37534" iyz="-0.00000" izz="0.22705"/>
      <origin rpy="0.00000 0.00000 0.00000" xyz="-0.00000 -0.00000 0.04000"/>
      <mass value="5.00000"/>
    </inertial>
    <visual name="wheelB_2">
      <material name="None"/>
      <origin rpy="0.00000 0.00000 0.00000" xyz="-0.00000 -0.00000 0.04000"/>
      <geometry>
        <mesh filename="../meshes/dae/Torus.001.dae" scale="0.32000 0.32000 0.80000"/>
      </geometry>
    </visual>
  </link>
  <link name="wheelB_3_link">
    <collision name="wheelB_3_collision">
      <origin rpy="0.00000 0.00000 0.00000" xyz="0.00000 0.00000 0.04000"/>
      <geometry>
        <mesh filename="../meshes/dae/Torus.002.dae" scale="0.32000 0.32000 0.80000"/>
      </geometry>
    </collision>
    <inertial>
      <inertia ixx="0.22705" ixy="0.00000" ixz="0.00000" iyy="0.37534" iyz="-0.00000" izz="0.22705"/>
      <origin rpy="0.00000 0.00000 0.00000" xyz="0.00000 -0.00000 0.04000"/>
      <mass value="5.00000"/>
    </inertial>
    <visual name="wheelB_3">
      <material name="None"/>
      <origin rpy="0.00000 0.00000 0.00000" xyz="0.00000 -0.00000 0.04000"/>
      <geometry>
        <mesh filename="../meshes/dae/Torus.002.dae" scale="0.32000 0.32000 0.80000"/>
      </geometry>
    </visual>
  </link>
  <link name="arm_1_link">
    <collision name="arm_1_collision">
      <origin rpy="0.00000 0.00000 0.00000" xyz="-0.72000 0.00000 0.01000"/>
      <geometry>
        <mesh filename="../meshes/dae/Cylinder.002.dae" scale="0.15000 0.17500 0.07500"/>
      </geometry>
    </collision>
    <visual name="arm_1">
      <material name="None"/>
      <origin rpy="0.00000 0.00000 0.00000" xyz="-0.72000 0.00000 0.01000"/>
      <geometry>
        <mesh filename="../meshes/dae/Cylinder.002.dae" scale="0.15000 0.17500 0.07500"/>
      </geometry>
    </visual>
    <inertial>
      <origin xyz="0 0 0" rpy="0 0 0"/>
      <mass value="5.0"/>
      <inertia ixx="0.1" ixy="0.0" ixz="0.0"
                iyy="0.1" iyz="0.0"
                izz="0.1"/>
    </inertial>
  </link>
  <link name="arm_2_link">
    <collision name="arm_2_collision">
      <origin rpy="0.00000 0.00000 0.00000" xyz="-0.76000 0.00000 0.01000"/>
      <geometry>
        <mesh filename="../meshes/dae/Cylinder.004.dae" scale="0.15000 0.17500 0.07500"/>
      </geometry>
    </collision>
    <visual name="arm_2">
      <material name="None"/>
      <origin rpy="0.00000 0.00000 0.00000" xyz="-0.76000 0.00000 0.01000"/>
      <geometry>
        <mesh filename="../meshes/dae/Cylinder.004.dae" scale="0.15000 0.17500 0.07500"/>
      </geometry>
    </visual>
    <inertial>
      <origin xyz="0 0 0" rpy="0 0 0"/>
      <mass value="5.0"/>
      <inertia ixx="0.1" ixy="0.0" ixz="0.0"
              iyy="0.1" iyz="0.0"
              izz="0.1"/>
    </inertial>
  </link>
  <link name="arm_3_link">
    <collision name="arm_3_collision">
      <origin rpy="0.00000 0.00000 0.00000" xyz="0.00000 0.00000 0.00000"/>
      <geometry>
        <mesh filename="../meshes/dae/Cylinder.001.dae" scale="0.15000 0.15000 0.35000"/>
      </geometry>
    </collision>
    <inertial>
      <inertia ixx="0.16965" ixy="0.00000" ixz="0.00000" iyy="0.16965" iyz="0.00000" izz="0.05265"/>
      <origin rpy="0.00000 0.00000 0.00000" xyz="0.00000 0.00000 0.00000"/>
      <mass value="3.51000"/>
    </inertial>
    <visual name="arm_3">
      <material name="None"/>
      <origin rpy="0.00000 0.00000 0.00000" xyz="0.00000 0.00000 0.00000"/>
      <geometry>
        <box size="0.30000 0.30000 0.70000"/>
      </geometry>
    </visual>
  </link>
  <link name="arm_4_link">
    <collision name="arm_4_collision">
      <origin rpy="0.00000 0.00000 0.00000" xyz="0.00000 0.00000 0.00000"/>
      <geometry>
        <mesh filename="../meshes/dae/Cylinder.003.dae" scale="0.07500 0.07500 0.75000"/>
      </geometry>
    </collision>
    <inertial>
      <inertia ixx="0.18891" ixy="0.00000" ixz="0.00000" iyy="0.18891" iyz="0.00000" izz="0.00281"/>
      <origin rpy="0.00000 0.00000 0.00000" xyz="0.00000 0.00000 -0.00000"/>
      <mass value="1.00000"/>
    </inertial>
    <visual name="arm_4">
      <material name="None"/>
      <origin rpy="0.00000 0.00000 0.00000" xyz="0.00000 0.00000 -0.00000"/>
      <geometry>
        <cylinder radius="0.07500" length="1.50000"/>
      </geometry>
    </visual>
  </link>
  <link name="base_endEffector_link">
    <collision name="base_endEffector_collision">
      <origin rpy="0.00000 0.00000 0.00000" xyz="0.00000 0.00000 -0.00000"/>
      <geometry>
        <mesh filename="../meshes/dae/Cube.001.dae" scale="0.20000 0.40000 0.05000"/>
      </geometry>
    </collision>
    <inertial>
      <inertia ixx="0.05417" ixy="0.00000" ixz="0.00000" iyy="0.01417" iyz="0.00000" izz="0.06667"/>
      <origin rpy="0.00000 0.00000 0.00000" xyz="0.00000 0.00000 0.00000"/>
      <mass value="1.00000"/>
    </inertial>
    <visual name="base_endEffector">
      <material name="None"/>
      <origin rpy="0.00000 0.00000 0.00000" xyz="0.00000 0.00000 0.00000"/>
      <geometry>
        <box size="0.40000 0.80000 0.10000"/>
      </geometry>
    </visual>
  </link>
  <link name="gripper_1_link">
    <collision name="gripper_1_collision">
      <origin rpy="1.57080 0.00000 0.00000" xyz="0.00000 0.00000 -0.00000"/>
      <geometry>
        <mesh filename="../meshes/dae/Cube.008.dae" scale="0.20000 0.04000 0.20000"/>
      </geometry>
    </collision>
    <inertial>
      <inertia ixx="0.01387" ixy="0.00000" ixz="0.00000" iyy="0.02667" iyz="-0.00000" izz="0.01387"/>
      <origin rpy="0.00000 0.00000 0.00000" xyz="0.00000 0.00000 -0.00000"/>
      <mass value="1.00000"/>
    </inertial>
    <visual name="gripper_1">
      <material name="None"/>
      <origin rpy="1.57080 0.00000 0.00000" xyz="0.00000 0.00000 -0.00000"/>
      <geometry>
        <box size="0.40000 0.08000 0.40000"/>
      </geometry>
    </visual>
  </link>
  <link name="gripper_2_link">
    <collision name="gripper_2_collision">
      <origin rpy="-1.57080 0.00000 0.00000" xyz="0.00000 -0.00000 -0.00000"/>
      <geometry>
        <mesh filename="../meshes/dae/Cube.009.dae" scale="0.20000 0.04000 0.20000"/>
      </geometry>
    </collision>
    <inertial>
      <inertia ixx="0.01387" ixy="0.00000" ixz="0.00000" iyy="0.02667" iyz="0.00000" izz="0.01387"/>
      <origin rpy="0.00000 0.00000 0.00000" xyz="0.00000 -0.00000 -0.00000"/>
      <mass value="1.00000"/>
    </inertial>
    <visual name="gripper_2">
      <material name="None"/>
      <origin rpy="-1.57080 0.00000 0.00000" xyz="0.00000 -0.00000 -0.00000"/>
      <geometry>
        <box size="0.40000 0.08000 0.40000"/>
      </geometry>
    </visual>
  </link>
  <link name="wheelA_1_link">
    <collision name="wheelA_1_collision">
      <origin rpy="0.00000 0.00000 0.00000" xyz="0.00000 0.00000 -0.04000"/>
      <geometry>
        <mesh filename="../meshes/dae/Torus.005.dae" scale="0.32000 0.32000 0.80000"/>
      </geometry>
    </collision>
    <inertial>
      <inertia ixx="0.22705" ixy="0.00000" ixz="0.00000" iyy="0.37534" iyz="-0.00000" izz="0.22705"/>
      <origin rpy="0.00000 0.00000 0.00000" xyz="0.00000 0.00000 -0.04000"/>
      <mass value="5.00000"/>
    </inertial>
    <visual name="wheelA_1">
      <material name="None"/>
      <origin rpy="0.00000 0.00000 0.00000" xyz="0.00000 0.00000 -0.04000"/>
      <geometry>
        <mesh filename="../meshes/dae/Torus.005.dae" scale="0.32000 0.32000 0.80000"/>
      </geometry>
    </visual>
  </link>
</robot>